2018-10-01 14:07:49,625 DEBUG    root            Loaded Command Group: [u'gcloud', u'compute', u'firewall_rules']
2018-10-01 14:07:49,633 DEBUG    root            Loaded Command Group: [u'gcloud', u'compute', u'firewall-rules', u'create']
2018-10-01 14:07:49,637 DEBUG    root            Running [gcloud.compute.firewall-rules.create] with arguments: [--allow: "[u'tcp:443']", --description: "JupyterSSH", NAME: "jup-ssh443"]
2018-10-01 14:07:49,784 INFO     ___FILE_ONLY___ Creating firewall...
2018-10-01 14:07:50,786 DEBUG    root            (gcloud.compute.firewall-rules.create) Could not fetch resource:
 - The resource 'projects/gcloud-assignment/global/firewalls/jup-ssh443' already exists
Traceback (most recent call last):
  File "/usr/lib/google-cloud-sdk/lib/googlecloudsdk/calliope/cli.py", line 848, in Execute
    resources = calliope_command.Run(cli=self, args=args)
  File "/usr/lib/google-cloud-sdk/lib/googlecloudsdk/calliope/backend.py", line 770, in Run
    resources = command_instance.Run(args)
  File "/usr/lib/google-cloud-sdk/lib/surface/compute/firewall_rules/create.py", line 120, in Run
    request)])
  File "/usr/lib/google-cloud-sdk/lib/googlecloudsdk/api_lib/compute/client_adapter.py", line 95, in MakeRequests
    errors, error_message='Could not fetch resource:')
  File "/usr/lib/google-cloud-sdk/lib/googlecloudsdk/api_lib/compute/utils.py", line 111, in RaiseToolException
    RaiseException(problems, calliope_exceptions.ToolException, error_message)
  File "/usr/lib/google-cloud-sdk/lib/googlecloudsdk/api_lib/compute/utils.py", line 123, in RaiseException
    errors))
ToolException: Could not fetch resource:
 - The resource 'projects/gcloud-assignment/global/firewalls/jup-ssh443' already exists

2018-10-01 14:07:50,788 ERROR    root            (gcloud.compute.firewall-rules.create) Could not fetch resource:
 - The resource 'projects/gcloud-assignment/global/firewalls/jup-ssh443' already exists

